# 条款 08. 不要在析构函数中抛出异常

## 引子

一般来说，C++ 不禁止析构函数抛出异常，但这个行为并不鼓励(事实上在 C++11 标准之后，析构函数被默认声明为 `nonexcept` 以防止用户在析构函数进行抛出异常操作)。考虑以下代码（这里我把书中示例的代码简单修改了一下更加方便说明例子）：

```C++
class Widge {
public:
    Widge(int a): a_(a) {}

    ~Widge() {
        std::cout << "Destructor called" << std::endl;

        if (a_ == 1) {
            throw 1;
        } else if (a_ == 2) {
            throw 1.0;
        } else {
            std::cout << "Safely Destructed" << std::endl;
        }
    }

private:
    int a_;
};

int main() {

    try{

        Widge w1(3);

        {
            Widge w2(1);
        }
    }
    catch(...) {
        std::cout << "Error catch." << std::endl;
    }

    return 0;
}
```

编译运行代码，程序输出：

```Bash
Destructor called
Destructor called
Safely Destructed
Error catch.
```

可以发现，由于 `w2` 是局部变量，所以在脱离作用域时会自动调用析构函数进行销毁。而在 `w2` 抛出异常时，C++ 会对该作用域中所有已构造对象依次调用析构函数以防止内存泄露，这里我们从输出可以看到 `w1` 的析构函数被调用了。最后 `w2` 的异常在 `catch` 被接住，程序正常退出。这样看来，貌似在 `Widge` 中的析构函数并没有引起什么不良后果。

但假如我们令 `w1` 的析构函数也抛出异常，如下所示：

```C++
class Widge {
    // ... 同上例
};

int main() {

    try{

        {
            Widge w1(2);    // 此时 w1 的析构函数也会抛出异常

            {
                Widge w2(1);
            }
        }
    }
    catch(...) {
        std::cout << "Error catch." << std::endl;
    }

    return 0;
}
```

这意味着，在 `w2` 析构函数调用过程抛出异常而导致 `w1` 的析构函数被调用而抛出另一个异常，这个时候 C++ 需要处理两个异常，编译运行结果如下所示：

```C++
Destructor called
Destructor called
terminate called after throwing an instance of 'double'
Aborted (core dumped)
```

可以发现，C++ 处理不了第二个异常导致程序崩溃了。这意味着**如果我们在某个对象的析构函数抛出异常，则在该对象的作用域有任何其他操作抛出异常而导致该对象的析构函数被调用时，系统将无法处理而直接崩溃**！因此我们需要一种其他做法来避免在析构函数中抛出异常。